<?xml version="1.0"?>
<robot name="arm_v1" xmlns:xacro="http://www.ros.org/wiki/xacro">


	<!-- BASE COMPONENTS -->
	<!-- ***********************************************************************************************-->

	<!-- Base Link -->
	<link name="base_link">
		<visual>
			<geometry>
				<box size="0.1 0.1 0.006"/>
			</geometry>
		</visual>	
		<collision>
			<geometry>
				<box size="0.1 0.1 0.006"/>
			</geometry>
		</collision>
	</link>

	<!-- Base Piece -->	
	<link name="cradle_base">
		<visual>
			<geometry>
				<mesh filename="package://robotics_controller/meshes/cradle_base.STL"/>
			</geometry>
			<origin rpy="0 0 0"/>
		</visual>
		<collision>
			<geometry>
				<mesh filename="package://robotics_controller/meshes/cradle_base.STL"/>
			</geometry> 
			<origin xyz="0 0 0" rpy="0 0 0"/>
		</collision>
		<inertial>
			<mass value="0.06476"/>
			<inertia ixx="0.0" ixy="0.0" ixz="0.0" iyy="0.0" iyz="0.00" izz="0.0"/>
		</inertial>
	</link>

	<!--Base link to cradle_base -->
	<joint name="base_joint" type="revolute">
		<parent link="base_link"/>
		<child link="cradle_base"/>
		<origin xyz="0 0 0.05" rpy="0 0 0"/>
		<axis xyz="0 0 1"/>
		<limit lower="-3.14" upper="3.14" effort="1000.0" velocity="1.0"/>
	</joint>

</robot>


