<!--

	<!-- ***********************************************************************************************-->

	<!-- LEFT COMPONENTS -->
	<!-- ***********************************************************************************************-->
	<!--Base to left joint -->
	<joint name="base_to_left" type="fixed">
		<parent link="cradle_base"/>
		<child link="rectangular_side_part"/>
		<origin xyz="-0.054 0.02756 0.060" rpy="0 1.57 0"/>
	</joint>


	<!--Side link-->
	<link name="rectangular_side_part">
		<visual>
			<geometry>
				<mesh filename="package://robotics_controller/meshes/rectangular_side_part.STL"/>
			</geometry>
			<origin xyz="0 0 0" rpy="0 3.14 0"/>
		</visual>
		<collision>
			<geometry>
				<mesh filename="package://robotics_controller/meshes/rectangular_side_part.STL"/>
			</geometry>
			<origin xyz="0 0 0" rpy="0 0 0"/>
		</collision>
		<inertial>
			<mass value="0.07043"/>
			<inertia ixx="0.000145" ixy="0.000038" ixz="0.00" iyy="0.0000755" iyz="0.00" izz="0.000219"/>
		</inertial>
	</link>

	<!-- Joint between left side servo and rectangular.. piece -->
	<joint name="left_servo_fixed" type="fixed">
		<parent link="rectangular_side_part"/>
		<child link="ax12a_2"/>
		<origin xyz = "0 0 0" rpy="0 0 1.57"/>
	</joint>

	<!-- Left side servo -->
	<link name="ax12a_2">
		<visual>
			<geometry>
				<mesh filename="package://robotics_controller/meshes/AX12.STL"/>
			</geometry>
			<origin xyz="0 0 0" rpy="0 0 0"/>
		</visual>
		<collision>
			<geometry>
				<mesh filename="package://robotics_controller/meshes/AX12.STL"/>
			</geometry>
			<origin xyz="0 0 0.0" rpy="0 0 0"/>
		</collision>
		<inertial>	
			<mass value="0.1"/>
			<inertia ixx="0.022" ixy="0.0" ixz="-0.0104" iyy="0.034681" iyz="0.0" izz="0.017194"/>
		</inertial>
	</link>
	

	<!-- joint from servo to servo mounting arm -->
	<joint name="ax_12_left_to_lever" type="revolute">
		<parent link="ax12a_2"/>
		<child link="servo_mounting_arm"/>
		<origin xyz="0 0 0.006" rpy="0 0 0"/>
		<limit lower="0.0" upper="3.14" effort="5.0" velocity="1.0"/>
		<axis xyz="0 0 1"/>
	</joint>
	

	<!-- Servo mounting arm -->
	<link name="servo_mounting_arm">
		<visual>
			<geometry>
				<mesh filename="package://robotics_controller/meshes/servo_mounting_arm.STL"/>
			</geometry>
			<origin xyz="0 0 0" rpy="0 0 0.0"/>
		</visual>
		<collision>
			<geometry>
				<mesh filename="package://robotics_controller/meshes/servo_mounting_arm.STL"/>
			</geometry>
			<origin xyz="0 0 0.0" rpy="0 0 0.0"/>
		</collision>
		<inertial>	
			<mass value="0.011"/>
			<inertia ixx="0.0000279" ixy="0.00" ixz="0.00" iyy="0.00" iyz="0.00" izz="0.0000282"/>
		</inertial>
	</link>

	<!-- Joint from servo arm to straight lever -->
	<joint name="servo_arm_to_straight_lever" type="continuous">
		<parent link="servo_mounting_arm"/>
		<child link="straight_lever"/>
		<origin xyz="0 0.07 0.006" rpy="0 0 -1.0"/>
		<axis xyz="0 0 1"/>
	</joint>


	<!-- Straight lever arm -->
	<link name="straight_lever">
		<visual>
			<geometry>
				<mesh filename="package://robotics_controller/meshes/straight_lever.STL"/>
			</geometry>
			<origin xyz="0 0 0" rpy="0 0 0.0"/>
		</visual>
		<collision>
			<geometry>
				<mesh filename="package://robotics_controller/meshes/straight_lever.STL"/>
			</geometry>
			<origin xyz="0 0 0" rpy="0 0 0.0"/>
		</collision>
		<inertial>
			<mass value="0.01901"/>
			<inertia ixx="0.000159" ixy="0.00" ixz="0.00" iyy="0.00" iyz="0.00" izz="0.000160"/>
		</inertial>
	</link>

	<!-- joint from straight lever arm to forearm lever -->
	<joint name="straight_to_forearm" type="continuous">
		<parent link="straight_lever"/>		
		<child link="forearm_lever"/>
		<origin xyz="0 0.156 0.012" rpy="0 0 -0.5"/>
		<axis xyz="0 0 1"/>
	</joint>	

	<!--Forearm lever -->
	<link name="forearm_lever">
		<visual>
			<geometry>
				<mesh filename="package://robotics_controller/meshes/forearm_lever.STL"/>
			</geometry>
			<origin xyz="0 0 0" rpy="0 0 0.0"/>
		</visual>
		<collision>
			<geometry>
				<mesh filename="package://robotics_controller/meshes/forearm_lever.STL"/>
			</geometry>
			<origin xyz="0 0 0" rpy="0 0 0.0"/>
		</collision>
		<inertial>
			<mass value="0.0325"/>
			<inertia ixx="0.000598" ixy="0.00" ixz="0.00" iyy="0.00" iyz="0.0000114" izz="0.00599"/>
		</inertial>
	</link>
	<!--- ********************************************************************************************** -->

	<!-- RIGHT SIDE COMPONENTS -->
	<!--- ********************************************************************************************** -->
	

	<!-- joint between cradle base and rh_side-->
	<joint name="base_to_right" type="fixed">
		<parent link="cradle_base"/>
		<child link="rh_side"/>
		<origin xyz="0.0515 0.02756 0.060" rpy="0 -1.57 0"/>
	</joint>

	<!-- Right hand side servo mount -->
	<link name="rh_side">
		<visual>
			<geometry>
				<mesh filename="package://robotics_controller/meshes/rh_side.STL"/>
			</geometry>			
			<origin xyz="0 0 0" rpy="0 0 0"/>
		</visual>
		<collision>
			<geometry>
				<mesh filename="package://robotics_controller/meshes/rh_side.STL"/>
			</geometry>
			<origin xyz="0 0 0" rpy="0 0 0"/>
		</collision>
		<inertial>
			<mass value="0.07441"/>
			<inertia ixx="0.000162" ixy="0.00" ixz="0.00" iyy="0.0000801" iyz="0.00" izz="0.000240"/>
		</inertial>	
	</link>

	<!-- Joint between servo and right hand side -->
	<joint name="rh_side_to_ax12a_3" type="fixed">
		<parent link="rh_side"/>
		<child link="ax12a_3"/>
		<origin xyz="0 0 0" rpy="0 0 1.57"/>
	</joint>

	
	<!-- Third servo -->
	<link name="ax12a_3">
		<visual>
			<geometry>
				<mesh filename="package://robotics_controller/meshes/AX12.STL"/>
			</geometry>
			<origin xyz="0 0 0" rpy="0 0 0"/>
		</visual>
		<collision>
			<geometry>
				<mesh filename="package://robotics_controller/meshes/AX12.STL"/>
			</geometry>
			<origin xyz="0 0 0.0" rpy="0 0 0"/>
		</collision>
		<inertial>	
			<mass value="0.1"/>
			<inertia ixx="0.022" ixy="0.0" ixz="-0.0104" iyy="0.034681" iyz="0.0" izz="0.017194"/>
		</inertial>
	</link>

	<!-- Revolute joint from right hand servo to central lever -->
	<joint name="servo_to_central_lever" type="revolute">
		<parent link="ax12a_3"/>
		<child link="central_lever"/>
		<limit lower="0.0" upper="3.14" effort="5.0" velocity="1.0"/>
		<origin xyz="0 0 0.011" rpy="0 0 -2.14"/>
		<axis xyz="0 0 1"/>
	</joint>

	<!-- Central Lever -->
	<link name="central_lever">
		<visual>
			<geometry>
				<mesh filename="package://robotics_controller/meshes/central_lever.STL"/>
			</geometry>
			<origin xyz="0 0 0" rpy="0 0 0"/>
		</visual>
		<collision>
			<geometry>
				<mesh filename="package://robotics_controller/meshes/central_lever.STL"/>
			</geometry>
			<origin xyz="0 0 0" rpy="0 0 0"/>
		</collision>
		<inertial>
			<mass value="0.02898"/>
			<inertia ixx="0.000265" ixy="0.0" ixz="0.0" iyy="0.0" iyz="0.0" izz="0.000266"/>
		</inertial>
	</link>

	<!-- Joint from right side servo mount to straight lever -->
	<joint name="rh_side_to_straight_lever_2" type="continuous">
		<parent link="rh_side"/>
		<child link="straight_lever_2"/>
		<origin xyz="0.03283 -0.07140 -0.006"/>
		<axis xyz="0 0 1"/>
	</joint>	


	<!-- Second straight lever arm -->
	<link name="straight_lever_2">
		<visual>
			<geometry>
				<mesh filename="package://robotics_controller/meshes/straight_lever.STL"/>
			</geometry>
			<origin xyz="0 0 0" rpy="0 0 0.0"/>
		</visual>
		<collision>
			<geometry>
				<mesh filename="package://robotics_controller/meshes/straight_lever.STL"/>
			</geometry>
			<origin xyz="0 0 0" rpy="0 0 0.0"/>
		</collision>
		<inertial>
			<mass value="0.01901"/>
			<inertia ixx="0.000159" ixy="0.00" ixz="0.00" iyy="0.00" iyz="0.00" izz="0.000160"/>
		</inertial>
	</link>

	<!-- Joint between central lever and triangular piece -->

	<joint name="central_lever_to_triangle" type="continuous">
		<parent link="central_lever"/>
		<child link="triangular_piece"/>
		<origin xyz="0 0.16 -0.012" rpy="0 0 0"/>
		<axis xyz="0 0 1"/>
	</joint>

	<!--
	 joint between triangular piece and straight lever 
	<joint name="straight_lever_to_triangle" type="continuous">
		<parent link="straight_lever"/>
		<child link="triangular_piece"/>
		<origin xyz="0.08568 0.13036 0" rpy="0 0 0"/>
	</joint>
	-->
	<!-- Triangular piece -->
	<link name="triangular_piece">
		<visual>
			<geometry>
				<mesh filename="package://robotics_controller/meshes/triangle_part.STL"/>
			</geometry>
			<origin xyz="0 0 0" rpy="0 0 0"/>
		</visual>
		<collision>
			<geometry>
				<mesh filename="package://robotics_controller/meshes/triangle_part.STL"/>
			</geometry>
			<origin xyz="0 0 0" rpy="0 0 0"/>
		</collision>
		<inertial>
			<mass value="0.02807"/>
			<inertia ixx="0.0000119" ixy="0.0" ixz="0.0" iyy="0.000035" iyz="0.0" izz="0.000047"/>
		</inertial>
	</link>
	
	<!--- ********************************************************************************************** -->

